2021-02-02 19:39:03.565343: W tensorflow/core/grappler/optimizers/data/auto_shard.cc:656] In AUTO-mode, and switching to DATA-based sharding, instead of FILE-based sharding as we cannot find appropriate reader dataset op(s) to shard. Error: Found an unshardable source dataset: name: "TensorSliceDataset/_3"
op: "TensorSliceDataset"
input: "Placeholder/_0"
input: "Placeholder/_1"
input: "Placeholder/_2"
attr {
  key: "Toutput_types"
  value {
    list {
      type: DT_INT32
      type: DT_INT64
      type: DT_INT32
    }
  }
}
attr {
  key: "output_shapes"
  value {
    list {
      shape {
        dim {
          size: 2048
        }
      }
      shape {
      }
      shape {
        dim {
          size: 2048
        }
      }
    }
  }
}

2021-02-02 19:39:03.632188: I tensorflow/compiler/mlir/mlir_graph_optimization_pass.cc:116] None of the MLIR optimization passes are enabled (registered 2)
2021-02-02 19:39:03.651134: I tensorflow/core/platform/profile_utils/cpu_utils.cc:112] CPU Frequency: 2200000000 Hz
Traceback (most recent call last):
  File "/home/pfrod/architectures/prosenet.py", line 100, in <module>
    trainer.train()
  File "/home/pfrod/anaconda3/envs/env_minus/lib/python3.7/site-packages/transformers/trainer_tf.py", line 549, in train
    self.distributed_training_steps(batch)
  File "/home/pfrod/anaconda3/envs/env_minus/lib/python3.7/site-packages/tensorflow/python/eager/def_function.py", line 828, in __call__
    result = self._call(*args, **kwds)
  File "/home/pfrod/anaconda3/envs/env_minus/lib/python3.7/site-packages/tensorflow/python/eager/def_function.py", line 871, in _call
    self._initialize(args, kwds, add_initializers_to=initializers)
  File "/home/pfrod/anaconda3/envs/env_minus/lib/python3.7/site-packages/tensorflow/python/eager/def_function.py", line 726, in _initialize
    *args, **kwds))
  File "/home/pfrod/anaconda3/envs/env_minus/lib/python3.7/site-packages/tensorflow/python/eager/function.py", line 2969, in _get_concrete_function_internal_garbage_collected
    graph_function, _ = self._maybe_define_function(args, kwargs)
  File "/home/pfrod/anaconda3/envs/env_minus/lib/python3.7/site-packages/tensorflow/python/eager/function.py", line 3361, in _maybe_define_function
    graph_function = self._create_graph_function(args, kwargs)
  File "/home/pfrod/anaconda3/envs/env_minus/lib/python3.7/site-packages/tensorflow/python/eager/function.py", line 3206, in _create_graph_function
    capture_by_value=self._capture_by_value),
  File "/home/pfrod/anaconda3/envs/env_minus/lib/python3.7/site-packages/tensorflow/python/framework/func_graph.py", line 990, in func_graph_from_py_func
    func_outputs = python_func(*func_args, **func_kwargs)
  File "/home/pfrod/anaconda3/envs/env_minus/lib/python3.7/site-packages/tensorflow/python/eager/def_function.py", line 634, in wrapped_fn
    out = weak_wrapped_fn().__wrapped__(*args, **kwds)
  File "/home/pfrod/anaconda3/envs/env_minus/lib/python3.7/site-packages/tensorflow/python/eager/function.py", line 3887, in bound_method_wrapper
    return wrapped_fn(*args, **kwargs)
  File "/home/pfrod/anaconda3/envs/env_minus/lib/python3.7/site-packages/tensorflow/python/framework/func_graph.py", line 977, in wrapper
    raise e.ag_error_metadata.to_exception(e)
ValueError: in user code:

    /home/pfrod/anaconda3/envs/env_minus/lib/python3.7/site-packages/transformers/trainer_tf.py:671 distributed_training_steps  *
        self.args.strategy.run(self.apply_gradients, inputs)
    /home/pfrod/anaconda3/envs/env_minus/lib/python3.7/site-packages/transformers/trainer_tf.py:643 apply_gradients  *
        self.training_step(reduced_features, reduced_labels, nb_instances_in_global_batch)
    /home/pfrod/anaconda3/envs/env_minus/lib/python3.7/site-packages/transformers/trainer_tf.py:616 training_step  *
        per_example_loss, _ = self.run_model(features, labels, True)
    /home/pfrod/anaconda3/envs/env_minus/lib/python3.7/site-packages/transformers/trainer_tf.py:718 run_model  *
        outputs = self.model(features, labels=labels, training=training)[:2]
    /home/pfrod/anaconda3/envs/env_minus/lib/python3.7/site-packages/transformers/models/longformer/modeling_tf_longformer.py:2000 call  *
        inputs = input_processing(
    /home/pfrod/anaconda3/envs/env_minus/lib/python3.7/site-packages/transformers/modeling_tf_utils.py:345 input_processing  *
        raise ValueError(

    ValueError: The following keyword arguments are not supported by this model: ['labels'].

